<?xml version="1.0" encoding="utf-8"?>
<!-- This URDF was automatically created by SolidWorks to URDF Exporter! Originally created by Stephen Brawner (brawner@gmail.com) 
     Commit Version: 1.6.0-1-g15f4949  Build Version: 1.6.7594.29634
     For more information, please see http://wiki.ros.org/sw_urdf_exporter -->
<robot name="metal_detector_bot_v2" xmlns:xacro="http://www.ros.org/wiki/xacro">

  <gazebo reference="base_link">
    <material>Gazebo/Black</material>
  </gazebo>
  <gazebo reference="Back_left_wheel_link">
    <material>Gazebo/Grey</material>
  </gazebo>
  <gazebo reference="Back_right_wheel_link">
    <material>Gazebo/Grey</material>
  </gazebo>
  <gazebo reference="Ball_caster_left_link">
    <material>Gazebo/Grey</material>
  </gazebo>
  <gazebo reference="Ball_caster_right_link">
    <material>Gazebo/Grey</material>
  </gazebo>
  <gazebo reference="Lidar_link">
    <material>Gazebo/Red</material>
  </gazebo>
  <gazebo reference="camera_link">
    <material>Gazebo/Blue</material>
  </gazebo>
  <gazebo reference="Metal_detector_arm_link">
    <material>Gazebo/Yellow</material>
  </gazebo>

  <link
    name="base_link">
    <inertial>
      <origin
        xyz="0.0352433046960833 0 0.06"
        rpy="1.5707 0 0" />
      <mass
        value="4.90119967390804" />
      <inertia
        ixx="0.0256279999650394"
        ixy="-0.0012824678178163"
        ixz="-7.30503953498976E-07"
        iyy="0.0653244834339538"
        iyz="-1.51918510606531E-08"
        izz="0.0470062321795552" />
    </inertial>
    <visual>
      <origin
        xyz="0 0 0"
        rpy="0 0 0" />
      <geometry>
        <mesh
          filename="package://metal_detector_bot/meshes/base_link.STL" />
      </geometry>
      <material
        name="">
        <color
          rgba="0.250980392156863 0.250980392156863 0.250980392156863 1" />
      </material>
    </visual>
    <collision>
      <origin
        xyz="0 0 0"
        rpy="0 0 0" />
      <geometry>
        <mesh
          filename="package://metal_detector_bot/meshes/base_link.STL" />
      </geometry>
    </collision>
  </link>
  <link
    name="Back_left_wheel_link">
    <inertial>
      <origin
        xyz="6.24500451351651E-16 -3.05311331771918E-16 0.0262587770530892"
        rpy="0 0 0" />
      <mass
        value="0.49830589190105" />
      <inertia
        ixx="0.000864068748819037"
        ixy="1.0842021724855E-19"
        ixz="1.91990872890094E-17"
        iyy="0.000864068748819036"
        iyz="-8.99787386295198E-18"
        izz="0.00167126892614855" />
    </inertial>
    <visual>
      <origin
        xyz="0 0 0"
        rpy="0 0 0" />
      <geometry>
        <mesh
          filename="package://metal_detector_bot/meshes/Back_left_wheel_link.STL" />
      </geometry>
      <material
        name="">
        <color
          rgba="0.298039215686275 0.298039215686275 0.298039215686275 1" />
      </material>
    </visual>
    <collision>
      <origin
        xyz="0 0 0"
        rpy="0 0 0" />
      <geometry>
        <mesh
          filename="package://metal_detector_bot/meshes/Back_left_wheel_link.STL" />
      </geometry>
    </collision>
  </link>
  <joint
    name="Back_left_wheel_joint"
    type="continuous">
    <origin
      xyz="0.1766 -0.15065 0.019"
      rpy="1.5708 1.1251 0" />
    <parent
      link="base_link" />
    <child
      link="Back_left_wheel_link" />
    <axis
      xyz="0 0 1" />
  </joint>
  <link
    name="Back_right_wheel_link">
    <inertial>
      <origin
        xyz="6.80011602582908E-16 5.55111512312578E-17 -0.0262587770530892"
        rpy="0 0 0" />
      <mass
        value="0.49830589190105" />
      <inertia
        ixx="0.000864068748819037"
        ixy="-5.7963138419527E-32"
        ixz="2.08834214869925E-17"
        iyy="0.000864068748819036"
        iyz="-8.64947253348298E-19"
        izz="0.00167126892614855" />
    </inertial>
    <visual>
      <origin
        xyz="0 0 0"
        rpy="3.142 0 0" />
      <geometry>
        <mesh
          filename="package://metal_detector_bot/meshes/Back_right_wheel_link.STL" />
      </geometry>
      <material
        name="">
        <color
          rgba="0.298039215686275 0.298039215686275 0.298039215686275 1" />
      </material>
    </visual>
    <collision>
      <origin
        xyz="0 0 0"
        rpy="0 0 0" />
      <geometry>
        <mesh
          filename="package://metal_detector_bot/meshes/Back_right_wheel_link.STL" />
      </geometry>
    </collision>
  </link>
  <joint
    name="Back_right_wheel_joint"
    type="continuous">
    <origin
      xyz="0.1766 0.15065 0.019"
      rpy="-1.5708 -1.3963 3.1416" />
    <parent
      link="base_link" />
    <child
      link="Back_right_wheel_link" />
    <axis
      xyz="0 0 1" />
  </joint>
  <link
    name="Ball_caster_left_link">
    <inertial>
      <origin
        xyz="6.93889390390723E-17 7.09154956979319E-15 0.0125000000000013"
        rpy="0 0 0" />
      <mass
        value="0.00818123086872342" />
      <inertia
        ixx="5.11326929295214E-07"
        ixy="0"
        ixz="-4.77927573339736E-55"
        iyy="5.11326929295214E-07"
        iyz="-1.06121239205001E-70"
        izz="5.11326929295214E-07" />
    </inertial>
    <visual>
      <origin
        xyz="0 0 0"
        rpy="0 0 0" />
      <geometry>
        <mesh
          filename="package://metal_detector_bot/meshes/Ball_caster_left_link.STL" />
      </geometry>
      <material
        name="">
        <color
          rgba="0.792156862745098 0.819607843137255 0.933333333333333 1" />
      </material>
    </visual>
    <collision>
      <origin
        xyz="0 0 0"
        rpy="0 0 0" />
      <geometry>
        <mesh
          filename="package://metal_detector_bot/meshes/Ball_caster_left_link.STL" />
      </geometry>
    </collision>
  </link>
  <joint
    name="Ball_caster_left_joint"
    type="continuous">
    <origin
      xyz="-0.06543 -0.07735 -0.04811"
      rpy="1.5708 0 0" />
    <parent
      link="base_link" />
    <child
      link="Ball_caster_left_link" />
    <axis
      xyz="0 0 1" />
  </joint>
  <link
    name="Ball_caster_right_link">
    <inertial>
      <origin
        xyz="1.38777878078145E-17 0 -0.0125"
        rpy="0 0 0" />
      <mass
        value="0.00818123086872342" />
      <inertia
        ixx="5.11326929295214E-07"
        ixy="0"
        ixz="-4.77927573339736E-55"
        iyy="5.11326929295214E-07"
        iyz="-1.06121239205001E-70"
        izz="5.11326929295214E-07" />
    </inertial>
    <visual>
      <origin
        xyz="0 0 0"
        rpy="0 0 0" />
      <geometry>
        <mesh
          filename="package://metal_detector_bot/meshes/Ball_caster_right_link.STL" />
      </geometry>
      <material
        name="">
        <color
          rgba="0.792156862745098 0.819607843137255 0.933333333333333 1" />
      </material>
    </visual>
    <collision>
      <origin
        xyz="0 0 0"
        rpy="0 0 0" />
      <geometry>
        <mesh
          filename="package://metal_detector_bot/meshes/Ball_caster_right_link.STL" />
      </geometry>
    </collision>
  </link>
  <joint
    name="Ball_caster_right_joint"
    type="continuous">
    <origin
      xyz="-0.06543 0.07735 -0.04811"
      rpy="1.5708 0 0" />
    <parent
      link="base_link" />
    <child
      link="Ball_caster_right_link" />
    <axis
      xyz="0 0 1" />
  </joint>
   <link
    name="Lidar_link">
    <inertial>
      <origin
        xyz="-6.79587614786925E-05 0.0127572143525103 -0.00287746273821438"
        rpy="0 0 0" />
      <mass
        value="0.0553297294575326" />
      <inertia
        ixx="1.77198970100708E-05"
        ixy="-5.03899483380146E-09"
        ixz="3.90650477574448E-08"
        iyy="3.29681799815038E-05"
        iyz="-2.52552357078286E-07"
        izz="1.80448127856945E-05" />
    </inertial>
    <visual>
      <origin
        xyz="0 0 0"
        rpy="1.5707 0 -1.5707" />
      <geometry>
        <mesh
          filename="package://metal_detector_bot/meshes/Lidar_link.STL" />
      </geometry>
      <material
        name="">
        <color
          rgba="1 0 0 1" />
      </material>
    </visual>
    <collision>
      <origin
        xyz="0 0 0"
        rpy="0 0 0" />
      <geometry>
        <mesh
          filename="package://metal_detector_bot/meshes/Lidar_link.STL" />
      </geometry>
    </collision>
  </link>
  <joint
    name="Lidar_joint"
    type="revolute">
    <origin
      xyz="-0.02 0 0.17"
      rpy="0 0 0" />
      <!--<origin
      xyz="0.28528 -0.51932 0.297"
      rpy="0 0 0" />-->

     
    <parent
      link="base_link" />
    <child
      link="Lidar_link" />
    <axis
      xyz="0 1 0" />
    <limit
      lower="0"
      upper="0"
      effort="0"
      velocity="0" />
  </joint>


   <!--The LIDAR plugin has been inserted by MBK from the website-->
  <!--https://classic.gazebosim.org/tutorials?tut=ros_gzplugins-->
  <!--Adding LIDAR Sensor to the Robot-->
  <!-- hokuyo -->
  <gazebo reference="Lidar_link">
    <sensor type="ray" name="head_hokuyo_sensor">
      <pose>0 0 0 0 0 3.142</pose>
      <visualize>true</visualize>
      <update_rate>40</update_rate>
      <ray>
        <scan>
          <horizontal>
            <samples>720</samples>
            <resolution>1</resolution>
            <min_angle>-1.570796</min_angle>
            <max_angle>1.570796</max_angle>
          </horizontal>
        </scan>
        <range>
          <min>0.10</min>
          <max>30.0</max>
          <resolution>0.01</resolution>
        </range>
        <noise>
          <type>gaussian</type>
          <!-- Noise parameters based on published spec for Hokuyo laser
               achieving "+-30mm" accuracy at range < 10m.  A mean of 0.0m and
               stddev of 0.01m will put 99.7% of samples within 0.03m of the true
               reading. -->
          <mean>0.0</mean>
          <stddev>0.01</stddev>
        </noise>
      </ray>
      <plugin name="gazebo_ros_head_hokuyo_controller" filename="libgazebo_ros_laser.so">
        <topicName>/scan</topicName>
        <frameName>Lidar_link</frameName>
      </plugin>
    </sensor>
  </gazebo>



  <link
    name="Metal_detector_arm_link">
    <inertial>
      <origin
        xyz="-0.140649491426954 -0.004 -8.44376651931711E-16"
        rpy="0 0 0" />
      <mass
        value="0.180271479688744" />
      <inertia
        ixx="0.000140221478425327"
        ixy="2.38536674196087E-21"
        ixz="4.79632406382748E-20"
        iyy="0.00124414564889824"
        iyz="1.12771898474177E-21"
        izz="0.00110584706625626" />
    </inertial>
    <visual>
      <origin
        xyz="0 0 0"
        rpy="0 0 0" />
      <geometry>
        <mesh
          filename="package://metal_detector_bot/meshes/Metal_detector_arm_link.STL" />
      </geometry>
      <material
        name="">
        <color
          rgba="1 0.937254901960784 0.137254901960784 1" />
      </material>
    </visual>
    <collision>
      <origin
        xyz="0 0 0"
        rpy="0 0 0" />
      <geometry>
        <mesh
          filename="package://metal_detector_bot/meshes/Metal_detector_arm_link.STL" />
      </geometry>
    </collision>
  </link>
  <joint
    name="Metal_detector_plate_joint"
    type="continuous">
    <origin
      xyz="-0.1143 0 -0.008"
      rpy="1.5708 0 0.0071867" />
    <parent
      link="base_link" />
    <child
      link="Metal_detector_arm_link" />
    <axis
      xyz="0 1 0" />
  </joint>
  <!--Differential drive plugin inserted by MBK-->
  <!-- This is necessary to move the robot using cmd_vel -->
  <!-- The plugin is taken from the website -->
  <!-- https://kiranpalla.com/autonomous-navigation-ros-differential-drive-robot-simulation/simple-navigation-with-differential-drive-plugin/ -->

  <gazebo>
    <plugin name="differential_drive_controller" filename="libgazebo_ros_diff_drive.so">
      <alwaysOn>true</alwaysOn>
      <legacyMode>false</legacyMode>
      <updateRate>40</updateRate>
      <leftJoint>Back_left_wheel_joint</leftJoint>
      <rightJoint>Back_right_wheel_joint</rightJoint>
      <wheelSeparation>0.2794</wheelSeparation>
      <wheelDiameter>0.1524</wheelDiameter>
      <torque>20</torque>
      <wheelTorque>5</wheelTorque>
      <wheelAcceleration>0</wheelAcceleration>
      <commandTopic>/cmd_vel</commandTopic>
      <odometryTopic>/odom</odometryTopic>
      <odometryFrame>odom</odometryFrame>
      <robotBaseFrame>base_link</robotBaseFrame>
      <publishWheelTF>true</publishWheelTF>
      <publishOdomTF>true</publishOdomTF>
      <publishWheelJointState>true</publishWheelJointState>
 
    </plugin>

  <plugin name="gazebo_ros_control" filename="libgazebo_ros_contol.so">
        <!-- <robotNamespace>/</robotNamespace> -->
  </plugin>

  <plugin name="joint_state_publisher" filename="libgazebo_ros_joint_state_publisher.so">
      <jointName> Ball_caster_left_joint , Ball_caster_right_joint, Lidar_joint, Metal_detector_plate_joint
      </jointName>
  </plugin>
</gazebo>
</robot>
